<?xml version="1.0" ?>
<sdf version="1.6">
  <world name="basic_physics_world">
    <!-- Physics engine configuration -->
    <physics type="ode">
      <max_step_size>0.001</max_step_size>
      <real_time_factor>1.0</real_time_factor>
      <real_time_update_rate>1000.0</real_time_update_rate>
      <gravity>0 0 -9.8</gravity>

      <!-- ODE solver parameters -->
      <ode>
        <solver>
          <type>quick</type>
          <iters>10</iters>
          <sor>1.3</sor>
        </solver>
        <constraints>
          <cfm>0.0</cfm>
          <erp>0.2</erp>
          <contact_max_correcting_vel>100.0</contact_max_correcting_vel>
          <contact_surface_layer>0.001</contact_surface_layer>
        </constraints>
      </ode>
    </physics>

    <!-- Lighting -->
    <light name="sun" type="directional">
      <cast_shadows>true</cast_shadows>
      <pose>0 0 10 0 0 0</pose>
      <diffuse>0.8 0.8 0.8 1</diffuse>
      <specular>0.2 0.2 0.2 1</specular>
      <attenuation>
        <range>1000</range>
        <constant>0.9</constant>
        <linear>0.01</linear>
        <quadratic>0.001</quadratic>
      </attenuation>
      <direction>-0.5 0.1 -0.9</direction>
    </light>

    <!-- Ground plane -->
    <include>
      <uri>model://ground_plane</uri>
    </include>

    <!-- Sky -->
    <scene>
      <ambient>0.4 0.4 0.4 1</ambient>
      <background>0.7 0.7 0.7 1</background>
      <shadows>true</shadows>
    </scene>

    <!-- Example objects to demonstrate physics -->

    <!-- Static box -->
    <model name="static_box">
      <pose>2 0 0.5 0 0 0</pose>
      <link name="box_link">
        <inertial>
          <mass>1.0</mass>
          <inertia>
            <ixx>0.083</ixx>
            <ixy>0</ixy>
            <ixz>0</ixz>
            <iyy>0.083</iyy>
            <iyz>0</iyz>
            <izz>0.083</izz>
          </inertia>
        </inertial>
        <visual name="visual">
          <geometry>
            <box><size>1 1 1</size></box>
          </geometry>
          <material>
            <ambient>0.5 0.5 0.5 1</ambient>
            <diffuse>0.7 0.7 0.7 1</diffuse>
            <specular>0.1 0.1 0.1 1</specular>
          </material>
        </visual>
        <collision name="collision">
          <geometry>
            <box><size>1 1 1</size></box>
          </geometry>
        </collision>
      </link>
    </model>

    <!-- Dynamic sphere that will fall due to gravity -->
    <model name="falling_sphere">
      <pose>-2 0 3 0 0 0</pose>
      <link name="sphere_link">
        <inertial>
          <mass>0.5</mass>
          <inertia>
            <ixx>0.01</ixx>
            <ixy>0</ixy>
            <ixz>0</ixz>
            <iyy>0.01</iyy>
            <iyz>0</iyz>
            <izz>0.01</izz>
          </inertia>
        </inertial>
        <visual name="visual">
          <geometry>
            <sphere><radius>0.2</radius></sphere>
          </geometry>
          <material>
            <ambient>1 0 0 1</ambient>
            <diffuse>1 0 0 1</diffuse>
            <specular>0.5 0.5 0.5 1</specular>
          </material>
        </visual>
        <collision name="collision">
          <geometry>
            <sphere><radius>0.2</radius></sphere>
          </geometry>
        </collision>
      </link>
    </model>

    <!-- Dynamic cylinder on a ramp to demonstrate sliding -->
    <model name="ramp">
      <pose>0 -2 0.5 0 0 -0.3</pose>
      <link name="ramp_link">
        <inertial>
          <mass>10.0</mass>
          <inertia>
            <ixx>1.0</ixx>
            <ixy>0</ixy>
            <ixz>0</ixz>
            <iyy>1.0</iyy>
            <iyz>0</iyz>
            <izz>1.0</izz>
          </inertia>
        </inertial>
        <visual name="visual">
          <geometry>
            <box><size>2 0.2 1</size></box>
          </geometry>
          <material>
            <ambient>0 0.5 0 1</ambient>
            <diffuse>0 0.8 0 1</diffuse>
            <specular>0.3 0.3 0.3 1</specular>
          </material>
        </visual>
        <collision name="collision">
          <geometry>
            <box><size>2 0.2 1</size></box>
          </geometry>
        </collision>
      </link>
    </model>

    <!-- A small box on the ramp that will slide down -->
    <model name="sliding_box">
      <pose>0.5 -2 0.8 0 0 0</pose>
      <link name="box_link">
        <inertial>
          <mass>0.2</mass>
          <inertia>
            <ixx>0.0067</ixx>
            <ixy>0</ixy>
            <ixz>0</ixz>
            <iyy>0.0067</iyy>
            <iyz>0</iyz>
            <izz>0.0067</izz>
          </inertia>
        </inertial>
        <visual name="visual">
          <geometry>
            <box><size>0.2 0.2 0.2</size></box>
          </geometry>
          <material>
            <ambient>0 0 1 1</ambient>
            <diffuse>0 0 1 1</diffuse>
            <specular>0.5 0.5 0.5 1</specular>
          </material>
        </visual>
        <collision name="collision">
          <geometry>
            <box><size>0.2 0.2 0.2</size></box>
          </geometry>
        </collision>
      </link>
    </model>

    <!-- A pendulum to demonstrate constraints -->
    <model name="pendulum_base">
      <pose>0 2 1 0 0 0</pose>
      <link name="base_link">
        <inertial>
          <mass>2.0</mass>
          <inertia>
            <ixx>0.1</ixx>
            <ixy>0</ixy>
            <ixz>0</ixz>
            <iyy>0.1</iyy>
            <iyz>0</iyz>
            <izz>0.1</izz>
          </inertia>
        </inertial>
        <visual name="visual">
          <geometry>
            <box><size>0.3 0.3 0.3</size></box>
          </geometry>
          <material>
            <ambient>0.5 0.2 0.8 1</ambient>
            <diffuse>0.8 0.4 1 1</diffuse>
            <specular>0.3 0.3 0.3 1</specular>
          </material>
        </visual>
        <collision name="collision">
          <geometry>
            <box><size>0.3 0.3 0.3</size></box>
          </geometry>
        </collision>
      </link>
    </model>

    <model name="pendulum_ball">
      <pose>0 2 0.5 0 0 0</pose>
      <link name="ball_link">
        <inertial>
          <mass>0.5</mass>
          <inertia>
            <ixx>0.01</ixx>
            <ixy>0</ixy>
            <ixz>0</ixz>
            <iyy>0.01</iyy>
            <iyz>0</iyz>
            <izz>0.01</izz>
          </inertia>
        </inertial>
        <visual name="visual">
          <geometry>
            <sphere><radius>0.1</radius></sphere>
          </geometry>
          <material>
            <ambient>1 1 0 1</ambient>
            <diffuse>1 1 0 1</diffuse>
            <specular>0.5 0.5 0.5 1</specular>
          </material>
        </visual>
        <collision name="collision">
          <geometry>
            <sphere><radius>0.1</radius></sphere>
          </geometry>
        </collision>
      </link>
    </model>

    <!-- Joint connecting pendulum parts -->
    <joint name="pendulum_joint" type="revolute">
      <parent>pendulum_base::base_link</parent>
      <child>pendulum_ball::ball_link</child>
      <pose>0 0 0.15 0 0 0</pose>
      <axis>
        <xyz>0 1 0</xyz>
        <limit>
          <lower>-1.57</lower>
          <upper>1.57</upper>
          <effort>100</effort>
          <velocity>1</velocity>
        </limit>
      </axis>
    </joint>

  </world>
</sdf>